{
  "runnable": false,
  "phase": "seed",
  "error_type": "RuntimeError",
  "message": "Traceback (most recent call last):\n  File \"/home/wan00559/pipleline/utils/compile_and_run.py\", line 541, in compare_and_bench\n    raise ValueError(\nValueError: Outputs are not close (atol=0.001, rtol=0.001). max_abs_err=2.801e+00, mean_abs_err=3.373e-01\n"
}